[2025-10-07T10:16:12.347+0000] {local_task_job_runner.py:120} INFO - ::group::Pre task execution logs
[2025-10-07T10:16:12.379+0000] {taskinstance.py:2076} INFO - Dependencies all met for dep_context=non-requeueable deps ti=<TaskInstance: minio_to_snowflake.load_snowflake scheduled__2025-10-07T10:15:00+00:00 [queued]>
[2025-10-07T10:16:12.388+0000] {taskinstance.py:2076} INFO - Dependencies all met for dep_context=requeueable deps ti=<TaskInstance: minio_to_snowflake.load_snowflake scheduled__2025-10-07T10:15:00+00:00 [queued]>
[2025-10-07T10:16:12.389+0000] {taskinstance.py:2306} INFO - Starting attempt 1 of 2
[2025-10-07T10:16:12.407+0000] {taskinstance.py:2330} INFO - Executing <Task(PythonOperator): load_snowflake> on 2025-10-07 10:15:00+00:00
[2025-10-07T10:16:12.415+0000] {standard_task_runner.py:90} INFO - Running: ['***', 'tasks', 'run', 'minio_to_snowflake', 'load_snowflake', 'scheduled__2025-10-07T10:15:00+00:00', '--job-id', '7', '--raw', '--subdir', 'DAGS_FOLDER/minio_to_snowflake.py', '--cfg-path', '/tmp/tmpdu1h03v_']
[2025-10-07T10:16:12.418+0000] {logging_mixin.py:188} WARNING - /home/***/.local/lib/python3.12/site-packages/***/task/task_runner/standard_task_runner.py:62 DeprecationWarning: This process (pid=2972) is multi-threaded, use of fork() may lead to deadlocks in the child.
[2025-10-07T10:16:12.419+0000] {standard_task_runner.py:91} INFO - Job 7: Subtask load_snowflake
[2025-10-07T10:16:12.419+0000] {standard_task_runner.py:64} INFO - Started process 2985 to run task
[2025-10-07T10:16:12.499+0000] {task_command.py:426} INFO - Running <TaskInstance: minio_to_snowflake.load_snowflake scheduled__2025-10-07T10:15:00+00:00 [running]> on host 1a1020fea0b2
[2025-10-07T10:16:12.592+0000] {taskinstance.py:2648} INFO - Exporting env vars: AIRFLOW_CTX_DAG_OWNER='***' AIRFLOW_CTX_DAG_ID='minio_to_snowflake' AIRFLOW_CTX_TASK_ID='load_snowflake' AIRFLOW_CTX_EXECUTION_DATE='2025-10-07T10:15:00+00:00' AIRFLOW_CTX_TRY_NUMBER='1' AIRFLOW_CTX_DAG_RUN_ID='scheduled__2025-10-07T10:15:00+00:00'
[2025-10-07T10:16:12.593+0000] {taskinstance.py:430} INFO - ::endgroup::
[2025-10-07T10:16:12.622+0000] {connection.py:408} INFO - Snowflake Connector for Python Version: 3.11.0, Python Version: 3.12.4, Platform: Linux-6.6.87.2-microsoft-standard-WSL2-x86_64-with-glibc2.36
[2025-10-07T10:16:12.624+0000] {connection.py:1258} INFO - This connection is in OCSP Fail Open Mode. TLS Certificates would be checked for validity and revocation status. Any other Certificate Revocation related exceptions or OCSP Responder failures would be disregarded in favor of connectivity.
[2025-10-07T10:16:53.135+0000] {ocsp_snowflake.py:1079} ERROR - WARNING!!! Using fail-open to connect. Driver is connecting to an HTTPS endpoint without OCSP based Certificate Revocation checking as it could not obtain a valid OCSP Response to use from the CA OCSP responder. Details: 
 {'driver': 'PythonConnector', 'version': '3.11.0', 'eventType': 'RevocationCheckFailure', 'eventSubType': 'OCSPResponseFailedToConnectCacheServer|OCSPResponseFetchException', 'sfcPeerHost': 'sfc-sg-ds1-158-customer-stage.s3.amazonaws.com', 'certId': 'MEowBwYFKw4DAhoEFIh9pEReZ+p8lHdOQxicPs7kyHMSBBScXwDfqgHXMCs4iKK4bUqc8hGRgwITBn+USionzfP6wq4rAfkI7rnExg==', 'ocspRequestBase64': 'MFIwUDBOMEwwSjAHBgUrDgMCGgQUiH2kRF5n6nyUd05DGJw+zuTIcxIEFJxfAN+qAdcwKziIorhtSpzyEZGDAhMGf5RKKifN8/rCrisB+QjuucTG', 'ocspResponderURL': 'http://ocsp.rootg2.amazontrust.com', 'errorMessage': '254003: 254003: Could not fetch OCSP Response from server. Considerchecking your whitelists : Exception - HTTPConnectionPool(host=\'ocsp.rootg2.amazontrust.com\', port=80): Max retries exceeded with url: / (Caused by NameResolutionError("<urllib3.connection.HTTPConnection object at 0x7796edb1d520>: Failed to resolve \'ocsp.rootg2.amazontrust.com\' ([Errno -2] Name or service not known)"))', 'insecureMode': False, 'failOpen': True, 'cacheEnabled': True, 'cacheHit': False}
[2025-10-07T10:16:53.144+0000] {ocsp_snowflake.py:1079} ERROR - WARNING!!! Using fail-open to connect. Driver is connecting to an HTTPS endpoint without OCSP based Certificate Revocation checking as it could not obtain a valid OCSP Response to use from the CA OCSP responder. Details: 
 {'driver': 'PythonConnector', 'version': '3.11.0', 'eventType': 'RevocationCheckFailure', 'eventSubType': 'OCSPResponseFailedToConnectCacheServer|OCSPResponseFetchException|OCSPResponseFetchException', 'sfcPeerHost': 'sfc-sg-ds1-158-customer-stage.s3.amazonaws.com', 'certId': 'MEAwBwYFKw4DAhoEFIvBnoRbmB1hz1RpIRpouOMRM22QBBS/X7fRzt0fhvRbVazc1xDCDqmI5wIJAKcOSkw0grd/', 'ocspRequestBase64': 'MEgwRjBEMEIwQDAHBgUrDgMCGgQUi8GehFuYHWHPVGkhGmi44xEzbZAEFL9ft9HO3R+G9FtVrNzXEMIOqYjnAgkApw5KTDSCt38=', 'ocspResponderURL': 'http://o.ss2.us/', 'errorMessage': '254003: 254003: Could not fetch OCSP Response from server. Considerchecking your whitelists : Exception - HTTPConnectionPool(host=\'o.ss2.us\', port=80): Max retries exceeded with url: / (Caused by NameResolutionError("<urllib3.connection.HTTPConnection object at 0x7796edb1d1f0>: Failed to resolve \'o.ss2.us\' ([Errno -2] Name or service not known)"))', 'insecureMode': False, 'failOpen': True, 'cacheEnabled': True, 'cacheHit': False}
[2025-10-07T10:17:25.069+0000] {connectionpool.py:824} WARNING - Retrying (Retry(total=0, connect=None, read=None, redirect=None, status=None)) after connection broken by 'ProtocolError('Connection aborted.', RemoteDisconnected('Remote end closed connection without response'))': /?accelerate
[2025-10-07T10:17:26.080+0000] {storage_client.py:318} WARNING - GET with url b'https://sfc-sg-ds1-158-customer-stage.s3.amazonaws.com/?accelerate' failed for transient error: HTTPSConnectionPool(host='sfc-sg-ds1-158-customer-stage.s3.amazonaws.com', port=443): Max retries exceeded with url: /?accelerate (Caused by NewConnectionError('<snowflake.connector.vendored.urllib3.connection.HTTPSConnection object at 0x7796edb1e030>: Failed to establish a new connection: [Errno -2] Name or service not known'))
[2025-10-07T10:17:26.093+0000] {connectionpool.py:824} WARNING - Retrying (Retry(total=0, connect=None, read=None, redirect=None, status=None)) after connection broken by 'NewConnectionError('<snowflake.connector.vendored.urllib3.connection.HTTPSConnection object at 0x7796edb1f830>: Failed to establish a new connection: [Errno -2] Name or service not known')': /?accelerate
[2025-10-07T10:17:28.094+0000] {storage_client.py:318} WARNING - GET with url b'https://sfc-sg-ds1-158-customer-stage.s3.amazonaws.com/?accelerate' failed for transient error: HTTPSConnectionPool(host='sfc-sg-ds1-158-customer-stage.s3.amazonaws.com', port=443): Max retries exceeded with url: /?accelerate (Caused by NewConnectionError('<snowflake.connector.vendored.urllib3.connection.HTTPSConnection object at 0x7796edb1fb60>: Failed to establish a new connection: [Errno -2] Name or service not known'))
[2025-10-07T10:17:28.101+0000] {connectionpool.py:824} WARNING - Retrying (Retry(total=0, connect=None, read=None, redirect=None, status=None)) after connection broken by 'NewConnectionError('<snowflake.connector.vendored.urllib3.connection.HTTPSConnection object at 0x7796edb1cb00>: Failed to establish a new connection: [Errno -2] Name or service not known')': /?accelerate
[2025-10-07T10:17:32.106+0000] {storage_client.py:318} WARNING - GET with url b'https://sfc-sg-ds1-158-customer-stage.s3.amazonaws.com/?accelerate' failed for transient error: HTTPSConnectionPool(host='sfc-sg-ds1-158-customer-stage.s3.amazonaws.com', port=443): Max retries exceeded with url: /?accelerate (Caused by NewConnectionError('<snowflake.connector.vendored.urllib3.connection.HTTPSConnection object at 0x7796edb1f050>: Failed to establish a new connection: [Errno -2] Name or service not known'))
[2025-10-07T10:17:46.256+0000] {logging_mixin.py:188} INFO - Uploaded /tmp/minio_downloads/1759829917.json to Snowflake stage
[2025-10-07T10:17:50.652+0000] {logging_mixin.py:188} INFO - Uploaded /tmp/minio_downloads/1759829930.json to Snowflake stage
[2025-10-07T10:17:51.950+0000] {logging_mixin.py:188} INFO - Uploaded /tmp/minio_downloads/1759829942.json to Snowflake stage
[2025-10-07T10:17:53.854+0000] {logging_mixin.py:188} INFO - Uploaded /tmp/minio_downloads/1759829955.json to Snowflake stage
[2025-10-07T10:17:55.775+0000] {logging_mixin.py:188} INFO - Uploaded /tmp/minio_downloads/1759829968.json to Snowflake stage
[2025-10-07T10:17:57.267+0000] {logging_mixin.py:188} INFO - Uploaded /tmp/minio_downloads/1759829981.json to Snowflake stage
[2025-10-07T10:17:59.171+0000] {logging_mixin.py:188} INFO - Uploaded /tmp/minio_downloads/1759829994.json to Snowflake stage
[2025-10-07T10:18:00.263+0000] {logging_mixin.py:188} INFO - Uploaded /tmp/minio_downloads/1759830008.json to Snowflake stage
[2025-10-07T10:18:01.484+0000] {logging_mixin.py:188} INFO - Uploaded /tmp/minio_downloads/1759830021.json to Snowflake stage
[2025-10-07T10:18:03.043+0000] {logging_mixin.py:188} INFO - Uploaded /tmp/minio_downloads/1759830034.json to Snowflake stage
[2025-10-07T10:18:04.614+0000] {logging_mixin.py:188} INFO - Uploaded /tmp/minio_downloads/1759830047.json to Snowflake stage
[2025-10-07T10:18:07.117+0000] {logging_mixin.py:188} INFO - Uploaded /tmp/minio_downloads/1759830060.json to Snowflake stage
[2025-10-07T10:18:09.067+0000] {logging_mixin.py:188} INFO - Uploaded /tmp/minio_downloads/1759830072.json to Snowflake stage
[2025-10-07T10:18:11.268+0000] {logging_mixin.py:188} INFO - Uploaded /tmp/minio_downloads/1759830085.json to Snowflake stage
[2025-10-07T10:18:12.572+0000] {logging_mixin.py:188} INFO - Uploaded /tmp/minio_downloads/1759830098.json to Snowflake stage
[2025-10-07T10:18:13.744+0000] {logging_mixin.py:188} INFO - Uploaded /tmp/minio_downloads/1759830112.json to Snowflake stage
[2025-10-07T10:18:14.910+0000] {logging_mixin.py:188} INFO - Uploaded /tmp/minio_downloads/1759830125.json to Snowflake stage
[2025-10-07T10:18:15.863+0000] {logging_mixin.py:188} INFO - Uploaded /tmp/minio_downloads/1759830137.json to Snowflake stage
[2025-10-07T10:18:17.576+0000] {logging_mixin.py:188} INFO - Uploaded /tmp/minio_downloads/1759830150.json to Snowflake stage
[2025-10-07T10:18:19.267+0000] {logging_mixin.py:188} INFO - Uploaded /tmp/minio_downloads/1759830164.json to Snowflake stage
[2025-10-07T10:18:21.616+0000] {logging_mixin.py:188} INFO - Uploaded /tmp/minio_downloads/1759830177.json to Snowflake stage
[2025-10-07T10:18:25.274+0000] {logging_mixin.py:188} INFO - Uploaded /tmp/minio_downloads/1759830191.json to Snowflake stage
[2025-10-07T10:18:30.825+0000] {logging_mixin.py:188} INFO - Uploaded /tmp/minio_downloads/1759830204.json to Snowflake stage
[2025-10-07T10:18:39.814+0000] {logging_mixin.py:188} INFO - Uploaded /tmp/minio_downloads/1759830218.json to Snowflake stage
[2025-10-07T10:18:44.205+0000] {logging_mixin.py:188} INFO - Uploaded /tmp/minio_downloads/1759830233.json to Snowflake stage
[2025-10-07T10:18:46.041+0000] {logging_mixin.py:188} INFO - Uploaded /tmp/minio_downloads/1759830246.json to Snowflake stage
[2025-10-07T10:18:49.802+0000] {logging_mixin.py:188} INFO - Uploaded /tmp/minio_downloads/1759830259.json to Snowflake stage
[2025-10-07T10:18:55.908+0000] {logging_mixin.py:188} INFO - Uploaded /tmp/minio_downloads/1759830273.json to Snowflake stage
[2025-10-07T10:19:04.367+0000] {logging_mixin.py:188} INFO - Uploaded /tmp/minio_downloads/1759830288.json to Snowflake stage
[2025-10-07T10:19:10.878+0000] {logging_mixin.py:188} INFO - Uploaded /tmp/minio_downloads/1759830303.json to Snowflake stage
[2025-10-07T10:19:22.160+0000] {connectionpool.py:824} WARNING - Retrying (Retry(total=0, connect=None, read=None, redirect=None, status=None)) after connection broken by 'ProtocolError('Connection aborted.', RemoteDisconnected('Remote end closed connection without response'))': /t6r81000-s/tables/70535745545/1759830317.json.gz
[2025-10-07T10:19:31.162+0000] {storage_client.py:318} WARNING - PUT with url b'https://sfc-sg-ds1-158-customer-stage.s3.amazonaws.com/t6r81000-s/tables/70535745545/1759830317.json.gz' failed for transient error: HTTPSConnectionPool(host='sfc-sg-ds1-158-customer-stage.s3.amazonaws.com', port=443): Max retries exceeded with url: /t6r81000-s/tables/70535745545/1759830317.json.gz (Caused by NewConnectionError('<snowflake.connector.vendored.urllib3.connection.HTTPSConnection object at 0x7796eda6ef30>: Failed to establish a new connection: [Errno -3] Temporary failure in name resolution'))
[2025-10-07T10:19:34.699+0000] {connectionpool.py:824} WARNING - Retrying (Retry(total=0, connect=None, read=None, redirect=None, status=None)) after connection broken by 'NewConnectionError('<snowflake.connector.vendored.urllib3.connection.HTTPSConnection object at 0x7796eda6ed50>: Failed to establish a new connection: [Errno -5] No address associated with hostname')': /t6r81000-s/tables/70535745545/1759830317.json.gz
[2025-10-07T10:19:46.710+0000] {logging_mixin.py:188} INFO - Uploaded /tmp/minio_downloads/1759830317.json to Snowflake stage
[2025-10-07T10:19:56.890+0000] {connectionpool.py:824} WARNING - Retrying (Retry(total=0, connect=None, read=None, redirect=None, status=None)) after connection broken by 'ProtocolError('Connection aborted.', RemoteDisconnected('Remote end closed connection without response'))': /t6r81000-s/tables/70535745545/1759830332.json.gz
[2025-10-07T10:23:00.445+0000] {storage_client.py:318} WARNING - PUT with url b'https://sfc-sg-ds1-158-customer-stage.s3.amazonaws.com/t6r81000-s/tables/70535745545/1759830332.json.gz' failed for transient error: HTTPSConnectionPool(host='sfc-sg-ds1-158-customer-stage.s3.amazonaws.com', port=443): Max retries exceeded with url: /t6r81000-s/tables/70535745545/1759830332.json.gz (Caused by ProtocolError('Connection aborted.', RemoteDisconnected('Remote end closed connection without response')))
[2025-10-07T10:23:00.684+0000] {connectionpool.py:824} WARNING - Retrying (Retry(total=0, connect=None, read=None, redirect=None, status=None)) after connection broken by 'NewConnectionError('<snowflake.connector.vendored.urllib3.connection.HTTPSConnection object at 0x7796ede5b740>: Failed to establish a new connection: [Errno -2] Name or service not known')': /t6r81000-s/tables/70535745545/1759830332.json.gz
[2025-10-07T10:23:02.755+0000] {storage_client.py:318} WARNING - PUT with url b'https://sfc-sg-ds1-158-customer-stage.s3.amazonaws.com/t6r81000-s/tables/70535745545/1759830332.json.gz' failed for transient error: HTTPSConnectionPool(host='sfc-sg-ds1-158-customer-stage.s3.amazonaws.com', port=443): Max retries exceeded with url: /t6r81000-s/tables/70535745545/1759830332.json.gz (Caused by NewConnectionError('<snowflake.connector.vendored.urllib3.connection.HTTPSConnection object at 0x7796ede93680>: Failed to establish a new connection: [Errno -2] Name or service not known'))
[2025-10-07T10:23:02.823+0000] {connectionpool.py:824} WARNING - Retrying (Retry(total=0, connect=None, read=None, redirect=None, status=None)) after connection broken by 'NewConnectionError('<snowflake.connector.vendored.urllib3.connection.HTTPSConnection object at 0x7796ede93fe0>: Failed to establish a new connection: [Errno -2] Name or service not known')': /t6r81000-s/tables/70535745545/1759830332.json.gz
[2025-10-07T10:23:06.891+0000] {storage_client.py:318} WARNING - PUT with url b'https://sfc-sg-ds1-158-customer-stage.s3.amazonaws.com/t6r81000-s/tables/70535745545/1759830332.json.gz' failed for transient error: HTTPSConnectionPool(host='sfc-sg-ds1-158-customer-stage.s3.amazonaws.com', port=443): Max retries exceeded with url: /t6r81000-s/tables/70535745545/1759830332.json.gz (Caused by NewConnectionError('<snowflake.connector.vendored.urllib3.connection.HTTPSConnection object at 0x7796ede93e00>: Failed to establish a new connection: [Errno -2] Name or service not known'))
[2025-10-07T10:23:06.982+0000] {connectionpool.py:824} WARNING - Retrying (Retry(total=0, connect=None, read=None, redirect=None, status=None)) after connection broken by 'NewConnectionError('<snowflake.connector.vendored.urllib3.connection.HTTPSConnection object at 0x7796ede92180>: Failed to establish a new connection: [Errno -2] Name or service not known')': /t6r81000-s/tables/70535745545/1759830332.json.gz
[2025-10-07T10:23:15.015+0000] {storage_client.py:318} WARNING - PUT with url b'https://sfc-sg-ds1-158-customer-stage.s3.amazonaws.com/t6r81000-s/tables/70535745545/1759830332.json.gz' failed for transient error: HTTPSConnectionPool(host='sfc-sg-ds1-158-customer-stage.s3.amazonaws.com', port=443): Max retries exceeded with url: /t6r81000-s/tables/70535745545/1759830332.json.gz (Caused by NewConnectionError('<snowflake.connector.vendored.urllib3.connection.HTTPSConnection object at 0x7796d44f5d60>: Failed to establish a new connection: [Errno -2] Name or service not known'))
[2025-10-07T10:23:15.184+0000] {connectionpool.py:824} WARNING - Retrying (Retry(total=0, connect=None, read=None, redirect=None, status=None)) after connection broken by 'NewConnectionError('<snowflake.connector.vendored.urllib3.connection.HTTPSConnection object at 0x7796d44f7f20>: Failed to establish a new connection: [Errno -2] Name or service not known')': /t6r81000-s/tables/70535745545/1759830332.json.gz
[2025-10-07T10:23:31.218+0000] {storage_client.py:318} WARNING - PUT with url b'https://sfc-sg-ds1-158-customer-stage.s3.amazonaws.com/t6r81000-s/tables/70535745545/1759830332.json.gz' failed for transient error: HTTPSConnectionPool(host='sfc-sg-ds1-158-customer-stage.s3.amazonaws.com', port=443): Max retries exceeded with url: /t6r81000-s/tables/70535745545/1759830332.json.gz (Caused by NewConnectionError('<snowflake.connector.vendored.urllib3.connection.HTTPSConnection object at 0x7796d44f7cb0>: Failed to establish a new connection: [Errno -2] Name or service not known'))
[2025-10-07T10:23:31.253+0000] {file_transfer_agent.py:606} ERROR - An exception was raised in <bound method SnowflakeStorageClient.upload_chunk of <snowflake.connector.s3_storage_client.SnowflakeS3RestClient object at 0x7796f3bf1a60>>
Traceback (most recent call last):
  File "/home/airflow/.local/lib/python3.12/site-packages/snowflake/connector/file_transfer_agent.py", line 603, in function_and_callback_wrapper
    work(*args, **kwargs),
    ^^^^^^^^^^^^^^^^^^^^^
  File "/home/airflow/.local/lib/python3.12/site-packages/snowflake/connector/storage_client.py", line 414, in upload_chunk
    self._upload_chunk(chunk_id, _data)
  File "/home/airflow/.local/lib/python3.12/site-packages/snowflake/connector/s3_storage_client.py", line 466, in _upload_chunk
    response = self._send_request_with_authentication_and_retry(
               ^^^^^^^^^^^^^^^^^^^^^^^^^^^^^^^^^^^^^^^^^^^^^^^^^
  File "/home/airflow/.local/lib/python3.12/site-packages/snowflake/connector/s3_storage_client.py", line 370, in _send_request_with_authentication_and_retry
    return self._send_request_with_retry(
           ^^^^^^^^^^^^^^^^^^^^^^^^^^^^^^
  File "/home/airflow/.local/lib/python3.12/site-packages/snowflake/connector/storage_client.py", line 321, in _send_request_with_retry
    raise RequestExceedMaxRetryError(
snowflake.connector.errors.RequestExceedMaxRetryError: PUT with url b'https://sfc-sg-ds1-158-customer-stage.s3.amazonaws.com/t6r81000-s/tables/70535745545/1759830332.json.gz' failed for exceeding maximum retries.
[2025-10-07T10:23:31.304+0000] {taskinstance.py:441} INFO - ::group::Post task execution logs
[2025-10-07T10:23:31.323+0000] {taskinstance.py:2905} ERROR - Task failed with exception
Traceback (most recent call last):
  File "/home/airflow/.local/lib/python3.12/site-packages/airflow/models/taskinstance.py", line 465, in _execute_task
    result = _execute_callable(context=context, **execute_callable_kwargs)
             ^^^^^^^^^^^^^^^^^^^^^^^^^^^^^^^^^^^^^^^^^^^^^^^^^^^^^^^^^^^^^
  File "/home/airflow/.local/lib/python3.12/site-packages/airflow/models/taskinstance.py", line 432, in _execute_callable
    return execute_callable(context=context, **execute_callable_kwargs)
           ^^^^^^^^^^^^^^^^^^^^^^^^^^^^^^^^^^^^^^^^^^^^^^^^^^^^^^^^^^^^
  File "/home/airflow/.local/lib/python3.12/site-packages/airflow/models/baseoperator.py", line 401, in wrapper
    return func(self, *args, **kwargs)
           ^^^^^^^^^^^^^^^^^^^^^^^^^^^
  File "/home/airflow/.local/lib/python3.12/site-packages/airflow/operators/python.py", line 235, in execute
    return_value = self.execute_callable()
                   ^^^^^^^^^^^^^^^^^^^^^^^
  File "/home/airflow/.local/lib/python3.12/site-packages/airflow/operators/python.py", line 252, in execute_callable
    return self.python_callable(*self.op_args, **self.op_kwargs)
           ^^^^^^^^^^^^^^^^^^^^^^^^^^^^^^^^^^^^^^^^^^^^^^^^^^^^^
  File "/opt/airflow/dags/minio_to_snowflake.py", line 56, in load_to_snowflake
    cur.execute(f"PUT file://{f} @%bronze_stock_quotes_raw")
  File "/home/airflow/.local/lib/python3.12/site-packages/snowflake/connector/cursor.py", line 1047, in execute
    data = sf_file_transfer_agent.result()
           ^^^^^^^^^^^^^^^^^^^^^^^^^^^^^^^
  File "/home/airflow/.local/lib/python3.12/site-packages/snowflake/connector/file_transfer_agent.py", line 740, in result
    Error.errorhandler_wrapper(
  File "/home/airflow/.local/lib/python3.12/site-packages/snowflake/connector/errors.py", line 290, in errorhandler_wrapper
    handed_over = Error.hand_to_other_handler(
                  ^^^^^^^^^^^^^^^^^^^^^^^^^^^^
  File "/home/airflow/.local/lib/python3.12/site-packages/snowflake/connector/errors.py", line 345, in hand_to_other_handler
    cursor.errorhandler(connection, cursor, error_class, error_value)
  File "/home/airflow/.local/lib/python3.12/site-packages/snowflake/connector/errors.py", line 221, in default_errorhandler
    raise error_class(
snowflake.connector.errors.OperationalError: 253003: 253003: While putting file(s) there was an error: 'PUT with url b'https://sfc-sg-ds1-158-customer-stage.s3.amazonaws.com/t6r81000-s/tables/70535745545/1759830332.json.gz' failed for exceeding maximum retries.', this might be caused by your access to the blob storage provider, or by Snowflake.
[2025-10-07T10:23:31.539+0000] {taskinstance.py:1206} INFO - Marking task as UP_FOR_RETRY. dag_id=minio_to_snowflake, task_id=load_snowflake, run_id=scheduled__2025-10-07T10:15:00+00:00, execution_date=20251007T101500, start_date=20251007T101612, end_date=20251007T102331
[2025-10-07T10:23:31.720+0000] {standard_task_runner.py:110} ERROR - Failed to execute job 7 for task load_snowflake (253003: 253003: While putting file(s) there was an error: 'PUT with url b'https://sfc-sg-ds1-158-customer-stage.s3.amazonaws.com/t6r81000-s/tables/70535745545/1759830332.json.gz' failed for exceeding maximum retries.', this might be caused by your access to the blob storage provider, or by Snowflake.; 2985)
[2025-10-07T10:23:31.966+0000] {local_task_job_runner.py:243} INFO - Task exited with return code 1
[2025-10-07T10:23:32.271+0000] {taskinstance.py:3503} INFO - 0 downstream tasks scheduled from follow-on schedule check
[2025-10-07T10:23:32.288+0000] {local_task_job_runner.py:222} INFO - ::endgroup::
