[2025-10-07T10:15:13.051+0000] {local_task_job_runner.py:120} INFO - ::group::Pre task execution logs
[2025-10-07T10:15:13.083+0000] {taskinstance.py:2076} INFO - Dependencies all met for dep_context=non-requeueable deps ti=<TaskInstance: minio_to_snowflake.load_snowflake scheduled__2025-10-07T10:14:00+00:00 [queued]>
[2025-10-07T10:15:13.096+0000] {taskinstance.py:2076} INFO - Dependencies all met for dep_context=requeueable deps ti=<TaskInstance: minio_to_snowflake.load_snowflake scheduled__2025-10-07T10:14:00+00:00 [queued]>
[2025-10-07T10:15:13.096+0000] {taskinstance.py:2306} INFO - Starting attempt 1 of 2
[2025-10-07T10:15:13.114+0000] {taskinstance.py:2330} INFO - Executing <Task(PythonOperator): load_snowflake> on 2025-10-07 10:14:00+00:00
[2025-10-07T10:15:13.127+0000] {standard_task_runner.py:90} INFO - Running: ['***', 'tasks', 'run', 'minio_to_snowflake', 'load_snowflake', 'scheduled__2025-10-07T10:14:00+00:00', '--job-id', '5', '--raw', '--subdir', 'DAGS_FOLDER/minio_to_snowflake.py', '--cfg-path', '/tmp/tmpmgizv5yt']
[2025-10-07T10:15:13.131+0000] {standard_task_runner.py:91} INFO - Job 5: Subtask load_snowflake
[2025-10-07T10:15:13.132+0000] {logging_mixin.py:188} WARNING - /home/***/.local/lib/python3.12/site-packages/***/task/task_runner/standard_task_runner.py:62 DeprecationWarning: This process (pid=2058) is multi-threaded, use of fork() may lead to deadlocks in the child.
[2025-10-07T10:15:13.133+0000] {standard_task_runner.py:64} INFO - Started process 2069 to run task
[2025-10-07T10:15:13.216+0000] {task_command.py:426} INFO - Running <TaskInstance: minio_to_snowflake.load_snowflake scheduled__2025-10-07T10:14:00+00:00 [running]> on host 1a1020fea0b2
[2025-10-07T10:15:13.329+0000] {taskinstance.py:2648} INFO - Exporting env vars: AIRFLOW_CTX_DAG_OWNER='***' AIRFLOW_CTX_DAG_ID='minio_to_snowflake' AIRFLOW_CTX_TASK_ID='load_snowflake' AIRFLOW_CTX_EXECUTION_DATE='2025-10-07T10:14:00+00:00' AIRFLOW_CTX_TRY_NUMBER='1' AIRFLOW_CTX_DAG_RUN_ID='scheduled__2025-10-07T10:14:00+00:00'
[2025-10-07T10:15:13.330+0000] {taskinstance.py:430} INFO - ::endgroup::
[2025-10-07T10:15:13.360+0000] {connection.py:408} INFO - Snowflake Connector for Python Version: 3.11.0, Python Version: 3.12.4, Platform: Linux-6.6.87.2-microsoft-standard-WSL2-x86_64-with-glibc2.36
[2025-10-07T10:15:13.362+0000] {connection.py:1258} INFO - This connection is in OCSP Fail Open Mode. TLS Certificates would be checked for validity and revocation status. Any other Certificate Revocation related exceptions or OCSP Responder failures would be disregarded in favor of connectivity.
[2025-10-07T10:15:17.370+0000] {connectionpool.py:824} WARNING - Retrying (Retry(total=0, connect=None, read=None, redirect=None, status=None)) after connection broken by 'NewConnectionError('<snowflake.connector.vendored.urllib3.connection.HTTPSConnection object at 0x799376657b90>: Failed to establish a new connection: [Errno -2] Name or service not known')': /session/v1/login-request?request_id=c765b2db-4e4e-4030-84bf-c6071f0fb623&databaseName=STOCKS_MDS&schemaName=COMMON&warehouse=COMPUTE_WH&request_guid=0ecbc5be-cfe7-46ef-8ee9-74126240b94b
[2025-10-07T10:15:20.838+0000] {network.py:1029} ERROR - Failed to get the response. Hanging? method: post, url: https://vo38192.ap-southeast-1.snowflakecomputing.com:443/session/v1/login-request?request_id=c765b2db-4e4e-4030-84bf-c6071f0fb623&databaseName=STOCKS_MDS&schemaName=COMMON&warehouse=COMPUTE_WH&request_guid=0ecbc5be-cfe7-46ef-8ee9-74126240b94b, headers:{'Content-Type': 'application/json', 'accept': 'application/snowflake', 'User-Agent': 'PythonConnector/3.11.0 (Linux-6.6.87.2-microsoft-standard-WSL2-x86_64-with-glibc2.36) CPython/3.12.4', 'Content-Encoding': 'gzip'}, data: {"data": {"CLIENT_APP_ID": "PythonConnector", "CLIENT_APP_VERSION": "3.11.0", "SVN_REVISION": null, "ACCOUNT_NAME": "vo38192", "LOGIN_NAME": "shadow", "CLIENT_ENVIRONMENT": {"APPLICATION": "PythonConnector", "OS": "Linux", "OS_VERSION": "Linux-6.6.87.2-microsoft-standard-WSL2-x86_64-with-glibc2.36", "PYTHON_VERSION": "3.12.4", "PYTHON_RUNTIME": "CPython", "PYTHON_COMPILER": "GCC 12.2.0", "OCSP_MODE": "FAIL_OPEN", "TRACING": 20, "LOGIN_TIMEOUT": null, "NETWORK_TIMEOUT": null, "SOCKET_TIMEOUT": null}, "PASSWORD": "**** "SESSION_PARAMETERS": {"CLIENT_PREFETCH_THREADS": 4}}}
[2025-10-07T10:15:21.892+0000] {connectionpool.py:824} WARNING - Retrying (Retry(total=0, connect=None, read=None, redirect=None, status=None)) after connection broken by 'NewConnectionError('<snowflake.connector.vendored.urllib3.connection.HTTPSConnection object at 0x7993944fc350>: Failed to establish a new connection: [Errno -2] Name or service not known')': /session/v1/login-request?request_id=6c13caa6-131c-48a5-bdfd-4057bb704c9c&databaseName=STOCKS_MDS&schemaName=COMMON&warehouse=COMPUTE_WH&request_guid=348274cf-ee39-4dbb-806f-5afa770b903c
[2025-10-07T10:15:21.898+0000] {taskinstance.py:441} INFO - ::group::Post task execution logs
[2025-10-07T10:15:21.899+0000] {taskinstance.py:2905} ERROR - Task failed with exception
Traceback (most recent call last):
  File "/home/airflow/.local/lib/python3.12/site-packages/snowflake/connector/connection.py", line 1392, in _authenticate
    auth.authenticate(
  File "/home/airflow/.local/lib/python3.12/site-packages/snowflake/connector/auth/_auth.py", line 250, in authenticate
    ret = self._rest._post_request(
          ^^^^^^^^^^^^^^^^^^^^^^^^^
  File "/home/airflow/.local/lib/python3.12/site-packages/snowflake/connector/network.py", line 734, in _post_request
    ret = self.fetch(
          ^^^^^^^^^^^
  File "/home/airflow/.local/lib/python3.12/site-packages/snowflake/connector/network.py", line 843, in fetch
    ret = self._request_exec_wrapper(
          ^^^^^^^^^^^^^^^^^^^^^^^^^^^
  File "/home/airflow/.local/lib/python3.12/site-packages/snowflake/connector/network.py", line 979, in _request_exec_wrapper
    raise e
  File "/home/airflow/.local/lib/python3.12/site-packages/snowflake/connector/network.py", line 895, in _request_exec_wrapper
    self._handle_unknown_error(method, full_url, headers, data, conn)
  File "/home/airflow/.local/lib/python3.12/site-packages/snowflake/connector/network.py", line 1034, in _handle_unknown_error
    Error.errorhandler_wrapper(
  File "/home/airflow/.local/lib/python3.12/site-packages/snowflake/connector/errors.py", line 290, in errorhandler_wrapper
    handed_over = Error.hand_to_other_handler(
                  ^^^^^^^^^^^^^^^^^^^^^^^^^^^^
  File "/home/airflow/.local/lib/python3.12/site-packages/snowflake/connector/errors.py", line 348, in hand_to_other_handler
    connection.errorhandler(connection, cursor, error_class, error_value)
  File "/home/airflow/.local/lib/python3.12/site-packages/snowflake/connector/errors.py", line 221, in default_errorhandler
    raise error_class(
snowflake.connector.errors.OperationalError: 250003: 250003: Failed to get the response. Hanging? method: post, url: https://vo38192.ap-southeast-1.snowflakecomputing.com:443/session/v1/login-request?request_id=c765b2db-4e4e-4030-84bf-c6071f0fb623&databaseName=STOCKS_MDS&schemaName=COMMON&warehouse=COMPUTE_WH&request_guid=0ecbc5be-cfe7-46ef-8ee9-74126240b94b

The above exception was the direct cause of the following exception:

Traceback (most recent call last):
  File "/home/airflow/.local/lib/python3.12/site-packages/airflow/models/taskinstance.py", line 465, in _execute_task
    result = _execute_callable(context=context, **execute_callable_kwargs)
             ^^^^^^^^^^^^^^^^^^^^^^^^^^^^^^^^^^^^^^^^^^^^^^^^^^^^^^^^^^^^^
  File "/home/airflow/.local/lib/python3.12/site-packages/airflow/models/taskinstance.py", line 432, in _execute_callable
    return execute_callable(context=context, **execute_callable_kwargs)
           ^^^^^^^^^^^^^^^^^^^^^^^^^^^^^^^^^^^^^^^^^^^^^^^^^^^^^^^^^^^^
  File "/home/airflow/.local/lib/python3.12/site-packages/airflow/models/baseoperator.py", line 401, in wrapper
    return func(self, *args, **kwargs)
           ^^^^^^^^^^^^^^^^^^^^^^^^^^^
  File "/home/airflow/.local/lib/python3.12/site-packages/airflow/operators/python.py", line 235, in execute
    return_value = self.execute_callable()
                   ^^^^^^^^^^^^^^^^^^^^^^^
  File "/home/airflow/.local/lib/python3.12/site-packages/airflow/operators/python.py", line 252, in execute_callable
    return self.python_callable(*self.op_args, **self.op_kwargs)
           ^^^^^^^^^^^^^^^^^^^^^^^^^^^^^^^^^^^^^^^^^^^^^^^^^^^^^
  File "/opt/airflow/dags/minio_to_snowflake.py", line 45, in load_to_snowflake
    conn = snowflake.connector.connect(
           ^^^^^^^^^^^^^^^^^^^^^^^^^^^^
  File "/home/airflow/.local/lib/python3.12/site-packages/snowflake/connector/__init__.py", line 55, in Connect
    return SnowflakeConnection(**kwargs)
           ^^^^^^^^^^^^^^^^^^^^^^^^^^^^^
  File "/home/airflow/.local/lib/python3.12/site-packages/snowflake/connector/connection.py", line 451, in __init__
    self.connect(**kwargs)
  File "/home/airflow/.local/lib/python3.12/site-packages/snowflake/connector/connection.py", line 756, in connect
    self.__open_connection()
  File "/home/airflow/.local/lib/python3.12/site-packages/snowflake/connector/connection.py", line 1084, in __open_connection
    self.authenticate_with_retry(self.auth_class)
  File "/home/airflow/.local/lib/python3.12/site-packages/snowflake/connector/connection.py", line 1364, in authenticate_with_retry
    self._authenticate(auth_instance)
  File "/home/airflow/.local/lib/python3.12/site-packages/snowflake/connector/connection.py", line 1436, in _authenticate
    raise auth_op from e
  File "/home/airflow/.local/lib/python3.12/site-packages/snowflake/connector/connection.py", line 1413, in _authenticate
    auth_instance.handle_timeout(
  File "/home/airflow/.local/lib/python3.12/site-packages/snowflake/connector/auth/by_plugin.py", line 212, in handle_timeout
    raise error
snowflake.connector.errors.OperationalError: 250001: 250001: Could not connect to Snowflake backend after 2 attempt(s).Aborting
[2025-10-07T10:15:21.919+0000] {taskinstance.py:1206} INFO - Marking task as UP_FOR_RETRY. dag_id=minio_to_snowflake, task_id=load_snowflake, run_id=scheduled__2025-10-07T10:14:00+00:00, execution_date=20251007T101400, start_date=20251007T101513, end_date=20251007T101521
[2025-10-07T10:15:21.936+0000] {standard_task_runner.py:110} ERROR - Failed to execute job 5 for task load_snowflake (250001: 250001: Could not connect to Snowflake backend after 2 attempt(s).Aborting; 2069)
[2025-10-07T10:15:21.958+0000] {local_task_job_runner.py:243} INFO - Task exited with return code 1
[2025-10-07T10:15:21.977+0000] {taskinstance.py:3503} INFO - 0 downstream tasks scheduled from follow-on schedule check
[2025-10-07T10:15:21.979+0000] {local_task_job_runner.py:222} INFO - ::endgroup::
