[2025-10-06T17:39:22.601+0000] {local_task_job_runner.py:120} INFO - ::group::Pre task execution logs
[2025-10-06T17:39:22.635+0000] {taskinstance.py:2076} INFO - Dependencies all met for dep_context=non-requeueable deps ti=<TaskInstance: minio_to_snowflake.load_snowflake scheduled__2025-10-06T17:33:00+00:00 [queued]>
[2025-10-06T17:39:22.647+0000] {taskinstance.py:2076} INFO - Dependencies all met for dep_context=requeueable deps ti=<TaskInstance: minio_to_snowflake.load_snowflake scheduled__2025-10-06T17:33:00+00:00 [queued]>
[2025-10-06T17:39:22.648+0000] {taskinstance.py:2306} INFO - Starting attempt 2 of 2
[2025-10-06T17:39:22.661+0000] {taskinstance.py:2330} INFO - Executing <Task(PythonOperator): load_snowflake> on 2025-10-06 17:33:00+00:00
[2025-10-06T17:39:22.671+0000] {standard_task_runner.py:90} INFO - Running: ['***', 'tasks', 'run', 'minio_to_snowflake', 'load_snowflake', 'scheduled__2025-10-06T17:33:00+00:00', '--job-id', '37', '--raw', '--subdir', 'DAGS_FOLDER/minio_to_snowflake.py', '--cfg-path', '/tmp/tmpkghp_8t0']
[2025-10-06T17:39:22.674+0000] {standard_task_runner.py:91} INFO - Job 37: Subtask load_snowflake
[2025-10-06T17:39:22.677+0000] {logging_mixin.py:188} WARNING - /home/***/.local/lib/python3.12/site-packages/***/task/task_runner/standard_task_runner.py:62 DeprecationWarning: This process (pid=15778) is multi-threaded, use of fork() may lead to deadlocks in the child.
[2025-10-06T17:39:22.678+0000] {standard_task_runner.py:64} INFO - Started process 15788 to run task
[2025-10-06T17:39:22.743+0000] {task_command.py:426} INFO - Running <TaskInstance: minio_to_snowflake.load_snowflake scheduled__2025-10-06T17:33:00+00:00 [running]> on host 24b9f9b681d0
[2025-10-06T17:39:22.840+0000] {taskinstance.py:2648} INFO - Exporting env vars: AIRFLOW_CTX_DAG_OWNER='***' AIRFLOW_CTX_DAG_ID='minio_to_snowflake' AIRFLOW_CTX_TASK_ID='load_snowflake' AIRFLOW_CTX_EXECUTION_DATE='2025-10-06T17:33:00+00:00' AIRFLOW_CTX_TRY_NUMBER='2' AIRFLOW_CTX_DAG_RUN_ID='scheduled__2025-10-06T17:33:00+00:00'
[2025-10-06T17:39:22.841+0000] {taskinstance.py:430} INFO - ::endgroup::
[2025-10-06T17:39:22.867+0000] {connection.py:408} INFO - Snowflake Connector for Python Version: 3.11.0, Python Version: 3.12.4, Platform: Linux-6.6.87.2-microsoft-standard-WSL2-x86_64-with-glibc2.36
[2025-10-06T17:39:22.868+0000] {connection.py:1258} INFO - This connection is in OCSP Fail Open Mode. TLS Certificates would be checked for validity and revocation status. Any other Certificate Revocation related exceptions or OCSP Responder failures would be disregarded in favor of connectivity.
[2025-10-06T17:39:24.929+0000] {logging_mixin.py:188} INFO - Uploaded /tmp/minio_downloads/1759738383.json to Snowflake stage
[2025-10-06T17:39:25.437+0000] {logging_mixin.py:188} INFO - Uploaded /tmp/minio_downloads/1759738397.json to Snowflake stage
[2025-10-06T17:39:25.916+0000] {logging_mixin.py:188} INFO - Uploaded /tmp/minio_downloads/1759738410.json to Snowflake stage
[2025-10-06T17:39:26.341+0000] {logging_mixin.py:188} INFO - Uploaded /tmp/minio_downloads/1759738431.json to Snowflake stage
[2025-10-06T17:39:26.884+0000] {logging_mixin.py:188} INFO - Uploaded /tmp/minio_downloads/1759738457.json to Snowflake stage
[2025-10-06T17:39:27.497+0000] {logging_mixin.py:188} INFO - Uploaded /tmp/minio_downloads/1759738476.json to Snowflake stage
[2025-10-06T17:39:28.007+0000] {logging_mixin.py:188} INFO - Uploaded /tmp/minio_downloads/1759738494.json to Snowflake stage
[2025-10-06T17:39:29.287+0000] {logging_mixin.py:188} INFO - Uploaded /tmp/minio_downloads/1759738512.json to Snowflake stage
[2025-10-06T17:39:30.087+0000] {logging_mixin.py:188} INFO - Uploaded /tmp/minio_downloads/1759738540.json to Snowflake stage
[2025-10-06T17:39:30.886+0000] {logging_mixin.py:188} INFO - Uploaded /tmp/minio_downloads/1759738577.json to Snowflake stage
[2025-10-06T17:39:33.930+0000] {logging_mixin.py:188} INFO - Uploaded /tmp/minio_downloads/1759738618.json to Snowflake stage
[2025-10-06T17:39:34.533+0000] {logging_mixin.py:188} INFO - Uploaded /tmp/minio_downloads/1759738633.json to Snowflake stage
[2025-10-06T17:39:35.041+0000] {logging_mixin.py:188} INFO - Uploaded /tmp/minio_downloads/1759738648.json to Snowflake stage
[2025-10-06T17:39:49.401+0000] {connectionpool.py:824} WARNING - Retrying (Retry(total=0, connect=None, read=None, redirect=None, status=None)) after connection broken by 'ProtocolError('Connection aborted.', RemoteDisconnected('Remote end closed connection without response'))': /?accelerate
[2025-10-06T17:39:54.414+0000] {storage_client.py:318} WARNING - GET with url b'https://sfc-sg-ds1-158-customer-stage.s3.amazonaws.com/?accelerate' failed for transient error: HTTPSConnectionPool(host='sfc-sg-ds1-158-customer-stage.s3.amazonaws.com', port=443): Max retries exceeded with url: /?accelerate (Caused by NewConnectionError('<snowflake.connector.vendored.urllib3.connection.HTTPSConnection object at 0x7e55920f5e50>: Failed to establish a new connection: [Errno -5] No address associated with hostname'))
[2025-10-06T17:39:54.492+0000] {connectionpool.py:824} WARNING - Retrying (Retry(total=0, connect=None, read=None, redirect=None, status=None)) after connection broken by 'NewConnectionError('<snowflake.connector.vendored.urllib3.connection.HTTPSConnection object at 0x7e55920f6510>: Failed to establish a new connection: [Errno -2] Name or service not known')': /?accelerate
[2025-10-06T17:40:01.974+0000] {logging_mixin.py:188} INFO - Uploaded /tmp/minio_downloads/1759738662.json to Snowflake stage
[2025-10-06T17:40:07.967+0000] {connectionpool.py:824} WARNING - Retrying (Retry(total=0, connect=None, read=None, redirect=None, status=None)) after connection broken by 'ProtocolError('Connection aborted.', RemoteDisconnected('Remote end closed connection without response'))': /?accelerate
[2025-10-06T17:40:26.952+0000] {storage_client.py:318} WARNING - GET with url b'https://sfc-sg-ds1-158-customer-stage.s3.amazonaws.com/?accelerate' failed for transient error: HTTPSConnectionPool(host='sfc-sg-ds1-158-customer-stage.s3.amazonaws.com', port=443): Max retries exceeded with url: /?accelerate (Caused by SSLError(SSLError("bad handshake: SysCallError(-1, 'Unexpected EOF')")))
[2025-10-06T17:40:34.967+0000] {connectionpool.py:824} WARNING - Retrying (Retry(total=0, connect=None, read=None, redirect=None, status=None)) after connection broken by 'NewConnectionError('<snowflake.connector.vendored.urllib3.connection.HTTPSConnection object at 0x7e55af86f2f0>: Failed to establish a new connection: [Errno -3] Temporary failure in name resolution')': /?accelerate
[2025-10-06T17:40:41.991+0000] {logging_mixin.py:188} INFO - Uploaded /tmp/minio_downloads/1759738675.json to Snowflake stage
[2025-10-06T17:40:47.994+0000] {connectionpool.py:824} WARNING - Retrying (Retry(total=0, connect=None, read=None, redirect=None, status=None)) after connection broken by 'ProtocolError('Connection aborted.', RemoteDisconnected('Remote end closed connection without response'))': /?accelerate
[2025-10-06T17:41:08.990+0000] {logging_mixin.py:188} INFO - Uploaded /tmp/minio_downloads/1759738689.json to Snowflake stage
[2025-10-06T17:41:17.574+0000] {connectionpool.py:824} WARNING - Retrying (Retry(total=0, connect=None, read=None, redirect=None, status=None)) after connection broken by 'ProtocolError('Connection aborted.', RemoteDisconnected('Remote end closed connection without response'))': /t6r81000-s/tables/70535745545/1759738703.json.gz
[2025-10-06T17:41:35.143+0000] {logging_mixin.py:188} INFO - Uploaded /tmp/minio_downloads/1759738703.json to Snowflake stage
[2025-10-06T17:41:41.132+0000] {connectionpool.py:824} WARNING - Retrying (Retry(total=0, connect=None, read=None, redirect=None, status=None)) after connection broken by 'ProtocolError('Connection aborted.', RemoteDisconnected('Remote end closed connection without response'))': /?accelerate
[2025-10-06T17:41:48.345+0000] {logging_mixin.py:188} INFO - Uploaded /tmp/minio_downloads/1759738717.json to Snowflake stage
[2025-10-06T17:41:54.354+0000] {connectionpool.py:824} WARNING - Retrying (Retry(total=0, connect=None, read=None, redirect=None, status=None)) after connection broken by 'ProtocolError('Connection aborted.', RemoteDisconnected('Remote end closed connection without response'))': /?accelerate
[2025-10-06T17:42:04.354+0000] {logging_mixin.py:188} INFO - Uploaded /tmp/minio_downloads/1759738732.json to Snowflake stage
[2025-10-06T17:42:10.355+0000] {connectionpool.py:824} WARNING - Retrying (Retry(total=0, connect=None, read=None, redirect=None, status=None)) after connection broken by 'ProtocolError('Connection aborted.', RemoteDisconnected('Remote end closed connection without response'))': /?accelerate
[2025-10-06T17:42:35.594+0000] {storage_client.py:318} WARNING - GET with url b'https://sfc-sg-ds1-158-customer-stage.s3.amazonaws.com/?accelerate' failed for transient error: HTTPSConnectionPool(host='sfc-sg-ds1-158-customer-stage.s3.amazonaws.com', port=443): Max retries exceeded with url: /?accelerate (Caused by SSLError(SSLError("bad handshake: SysCallError(-1, 'Unexpected EOF')")))
[2025-10-06T17:42:35.711+0000] {connectionpool.py:824} WARNING - Retrying (Retry(total=0, connect=None, read=None, redirect=None, status=None)) after connection broken by 'NewConnectionError('<snowflake.connector.vendored.urllib3.connection.HTTPSConnection object at 0x7e55af98f620>: Failed to establish a new connection: [Errno -2] Name or service not known')': /?accelerate
[2025-10-06T17:42:37.736+0000] {storage_client.py:318} WARNING - GET with url b'https://sfc-sg-ds1-158-customer-stage.s3.amazonaws.com/?accelerate' failed for transient error: HTTPSConnectionPool(host='sfc-sg-ds1-158-customer-stage.s3.amazonaws.com', port=443): Max retries exceeded with url: /?accelerate (Caused by NewConnectionError('<snowflake.connector.vendored.urllib3.connection.HTTPSConnection object at 0x7e55af94d070>: Failed to establish a new connection: [Errno -2] Name or service not known'))
[2025-10-06T17:42:37.742+0000] {connectionpool.py:824} WARNING - Retrying (Retry(total=0, connect=None, read=None, redirect=None, status=None)) after connection broken by 'NewConnectionError('<snowflake.connector.vendored.urllib3.connection.HTTPSConnection object at 0x7e55af94e450>: Failed to establish a new connection: [Errno -2] Name or service not known')': /?accelerate
[2025-10-07T01:54:05.865+0000] {storage_client.py:318} WARNING - GET with url b'https://sfc-sg-ds1-158-customer-stage.s3.amazonaws.com/?accelerate' failed for transient error: HTTPSConnectionPool(host='sfc-sg-ds1-158-customer-stage.s3.amazonaws.com', port=443): Max retries exceeded with url: /?accelerate (Caused by NewConnectionError('<snowflake.connector.vendored.urllib3.connection.HTTPSConnection object at 0x7e55af94ce30>: Failed to establish a new connection: [Errno -2] Name or service not known'))
[2025-10-07T01:54:06.011+0000] {connectionpool.py:824} WARNING - Retrying (Retry(total=0, connect=None, read=None, redirect=None, status=None)) after connection broken by 'NewConnectionError('<snowflake.connector.vendored.urllib3.connection.HTTPSConnection object at 0x7e55af94ecf0>: Failed to establish a new connection: [Errno -2] Name or service not known')': /?accelerate
[2025-10-07T01:54:14.082+0000] {storage_client.py:318} WARNING - GET with url b'https://sfc-sg-ds1-158-customer-stage.s3.amazonaws.com/?accelerate' failed for transient error: HTTPSConnectionPool(host='sfc-sg-ds1-158-customer-stage.s3.amazonaws.com', port=443): Max retries exceeded with url: /?accelerate (Caused by NewConnectionError('<snowflake.connector.vendored.urllib3.connection.HTTPSConnection object at 0x7e55af94eae0>: Failed to establish a new connection: [Errno -2] Name or service not known'))
[2025-10-07T01:54:14.236+0000] {connectionpool.py:824} WARNING - Retrying (Retry(total=0, connect=None, read=None, redirect=None, status=None)) after connection broken by 'NewConnectionError('<snowflake.connector.vendored.urllib3.connection.HTTPSConnection object at 0x7e55af94f650>: Failed to establish a new connection: [Errno -2] Name or service not known')': /?accelerate
[2025-10-07T08:31:27.621+0000] {storage_client.py:318} WARNING - GET with url b'https://sfc-sg-ds1-158-customer-stage.s3.amazonaws.com/?accelerate' failed for transient error: HTTPSConnectionPool(host='sfc-sg-ds1-158-customer-stage.s3.amazonaws.com', port=443): Max retries exceeded with url: /?accelerate (Caused by NewConnectionError('<snowflake.connector.vendored.urllib3.connection.HTTPSConnection object at 0x7e55af94ee40>: Failed to establish a new connection: [Errno -2] Name or service not known'))
[2025-10-07T08:31:27.881+0000] {taskinstance.py:441} INFO - ::group::Post task execution logs
[2025-10-07T08:31:27.905+0000] {taskinstance.py:2905} ERROR - Task failed with exception
Traceback (most recent call last):
  File "/home/airflow/.local/lib/python3.12/site-packages/airflow/models/taskinstance.py", line 465, in _execute_task
    result = _execute_callable(context=context, **execute_callable_kwargs)
             ^^^^^^^^^^^^^^^^^^^^^^^^^^^^^^^^^^^^^^^^^^^^^^^^^^^^^^^^^^^^^
  File "/home/airflow/.local/lib/python3.12/site-packages/airflow/models/taskinstance.py", line 432, in _execute_callable
    return execute_callable(context=context, **execute_callable_kwargs)
           ^^^^^^^^^^^^^^^^^^^^^^^^^^^^^^^^^^^^^^^^^^^^^^^^^^^^^^^^^^^^
  File "/home/airflow/.local/lib/python3.12/site-packages/airflow/models/baseoperator.py", line 401, in wrapper
    return func(self, *args, **kwargs)
           ^^^^^^^^^^^^^^^^^^^^^^^^^^^
  File "/home/airflow/.local/lib/python3.12/site-packages/airflow/operators/python.py", line 235, in execute
    return_value = self.execute_callable()
                   ^^^^^^^^^^^^^^^^^^^^^^^
  File "/home/airflow/.local/lib/python3.12/site-packages/airflow/operators/python.py", line 252, in execute_callable
    return self.python_callable(*self.op_args, **self.op_kwargs)
           ^^^^^^^^^^^^^^^^^^^^^^^^^^^^^^^^^^^^^^^^^^^^^^^^^^^^^
  File "/opt/airflow/dags/minio_to_snowflake.py", line 56, in load_to_snowflake
    cur.execute(f"PUT file://{f} @%bronze_stock_quotes_raw")
  File "/home/airflow/.local/lib/python3.12/site-packages/snowflake/connector/cursor.py", line 1046, in execute
    sf_file_transfer_agent.execute()
  File "/home/airflow/.local/lib/python3.12/site-packages/snowflake/connector/file_transfer_agent.py", line 398, in execute
    self._transfer_accelerate_config()
  File "/home/airflow/.local/lib/python3.12/site-packages/snowflake/connector/file_transfer_agent.py", line 697, in _transfer_accelerate_config
    client = self._create_file_transfer_client(self._file_metadata[0])
             ^^^^^^^^^^^^^^^^^^^^^^^^^^^^^^^^^^^^^^^^^^^^^^^^^^^^^^^^^
  File "/home/airflow/.local/lib/python3.12/site-packages/snowflake/connector/file_transfer_agent.py", line 676, in _create_file_transfer_client
    return SnowflakeS3RestClient(
           ^^^^^^^^^^^^^^^^^^^^^^
  File "/home/airflow/.local/lib/python3.12/site-packages/snowflake/connector/s3_storage_client.py", line 91, in __init__
    self.transfer_accelerate_config(use_accelerate_endpoint)
  File "/home/airflow/.local/lib/python3.12/site-packages/snowflake/connector/s3_storage_client.py", line 114, in transfer_accelerate_config
    use_accelerate_endpoint = self._get_bucket_accelerate_config(
                              ^^^^^^^^^^^^^^^^^^^^^^^^^^^^^^^^^^^
  File "/home/airflow/.local/lib/python3.12/site-packages/snowflake/connector/s3_storage_client.py", line 580, in _get_bucket_accelerate_config
    response = self._send_request_with_authentication_and_retry(
               ^^^^^^^^^^^^^^^^^^^^^^^^^^^^^^^^^^^^^^^^^^^^^^^^^
  File "/home/airflow/.local/lib/python3.12/site-packages/snowflake/connector/s3_storage_client.py", line 370, in _send_request_with_authentication_and_retry
    return self._send_request_with_retry(
           ^^^^^^^^^^^^^^^^^^^^^^^^^^^^^^
  File "/home/airflow/.local/lib/python3.12/site-packages/snowflake/connector/storage_client.py", line 321, in _send_request_with_retry
    raise RequestExceedMaxRetryError(
snowflake.connector.errors.RequestExceedMaxRetryError: GET with url b'https://sfc-sg-ds1-158-customer-stage.s3.amazonaws.com/?accelerate' failed for exceeding maximum retries.
[2025-10-07T08:31:28.045+0000] {taskinstance.py:1206} INFO - Marking task as FAILED. dag_id=minio_to_snowflake, task_id=load_snowflake, run_id=scheduled__2025-10-06T17:33:00+00:00, execution_date=20251006T173300, start_date=20251006T173922, end_date=20251007T083128
[2025-10-07T08:31:28.295+0000] {standard_task_runner.py:110} ERROR - Failed to execute job 37 for task load_snowflake (GET with url b'https://sfc-sg-ds1-158-customer-stage.s3.amazonaws.com/?accelerate' failed for exceeding maximum retries.; 15788)
[2025-10-07T08:31:28.459+0000] {local_task_job_runner.py:243} INFO - Task exited with return code 1
[2025-10-07T08:31:28.593+0000] {taskinstance.py:3503} INFO - 0 downstream tasks scheduled from follow-on schedule check
[2025-10-07T08:31:28.697+0000] {local_task_job_runner.py:222} INFO - ::endgroup::
